I'm sorry, but an uncaught exception occurred.

While running game code:
  File "game/script.rpy", line 347, in script
    scene bg enfermaria alpha 0.33
Exception: Image 'bg enfermaria' does not accept attributes 'alpha 0 .33'.

-- Full Traceback ------------------------------------------------------------

Full traceback:
  File "game/script.rpy", line 347, in script
    scene bg enfermaria alpha 0.33
  File "/home/zoenspi/Documentos/renpy-8.3.2-sdk/renpy/ast.py", line 1245, in execute
    show_imspec(self.imspec, atl=getattr(self, "atl", None))
  File "/home/zoenspi/Documentos/renpy-8.3.2-sdk/renpy/ast.py", line 1074, in show_imspec
    renpy.config.show(name,
  File "/home/zoenspi/Documentos/renpy-8.3.2-sdk/renpy/exports/displayexports.py", line 477, in show
    if not base.find_target() and renpy.config.missing_show:
  File "/home/zoenspi/Documentos/renpy-8.3.2-sdk/renpy/display/image.py", line 421, in find_target
    self.target = target._duplicate(a)
  File "/home/zoenspi/Documentos/renpy-8.3.2-sdk/renpy/display/displayable.py", line 249, in _duplicate
    args.extraneous()
  File "/home/zoenspi/Documentos/renpy-8.3.2-sdk/renpy/display/displayable.py", line 109, in extraneous
    raise Exception("Image '{}' does not accept attributes '{}'.".format(
Exception: Image 'bg enfermaria' does not accept attributes 'alpha 0 .33'.

Linux-6.9.3-76060903-generic-x86_64-with-glibc2.35 x86_64
Ren'Py 8.3.2.24090902
HogUSP 1.0
Thu Nov 28 01:26:03 2024
